Workbook

Sheet 1. Assumptions
A1: Cascade Health Plan HMO | CY2027 Medicare Advantage Bid — Assumptions & Inputs
A2: Illustrative model. Every figure is hypothetical and constructed for teaching purposes; none is drawn from an actual filed bid. Structure follows the CMS Bid Pricing Tool. Change any blue cell and the whole model recalculates.
A4: LEGEND
A5: Blue text | B5: Hardcoded input or scenario lever — edit these
A6: Black text | B6: Formula — do not overwrite
A7: Green text | B7: Link to another sheet in this workbook
A8: Shaded cell | B8: Key assumption — verify against the published CY2027 Rate Announcement before relying on it
A10: PLAN PROFILE
A11: Plan name | B11: Cascade Health Plan HMO
A12: Contract year (bid year) | B12: 2027
A13: Base experience year | B13: 2025
A14: Projection years | B14: =B12-B13
A15: Projected enrolled members | B15: 10000
A16: Member months | B16: =B15*12
A17: County (illustrative) | B17: Marion County
A18: Star rating driving CY2027 QBP | B18: 4 | C18: From the 2026 Star Ratings published Oct 2025 — known with certainty at the June 2026 bid deadline.
A20: RISK SCORE & NORMALIZATION
A21: Base period average RAF (CY2025) | B21: 1.082
A22: One-time item removed from base (PMPM) | B22: 4.5 | C22: Retroactive hospital settlement paid in CY2025 relating to CY2023 dates of service.
A23: Projected CY2027 raw RAF (v28) | B23: 1.212
A24: CY2027 normalization factor | B24: 1.045
A25: Coding intensity adjustment | B25: 0.059 | C25: Statutory minimum is 5.9%. Confirm the CY2027 value in the Rate Announcement.
A26: Payment RAF | B26: =B23/B24*(1-B25)
A28: PLAN-YEAR ADJUSTMENTS
A29: Hospital contract renegotiation (% of IP + OP) | B29: -0.02 | C29: Signed LOI, not yet executed — a live desk-review question.
A30: Post-acute utilization management program (PMPM) | B30: -2.8
A31: Induced utilization from richer benefit design (PMPM) | B31: 1.9
A32: New-to-Medicare mix shift, non-risk-score (PMPM) | B32: -1.6
A34: COST SHARING, ADMINISTRATION & MARGIN
A35: Original Medicare-equivalent cost sharing (% of allowed) | B35: 0.135 | C35: Actuarial value of Part A/B deductibles and coinsurance. The bid is priced at this level; anything richer is rebate-funded.
A36: General & administrative (PMPM) | B36: 52
A37: Sales, marketing & broker commissions (PMPM) | B37: 22
A38: Quality improvement activities (PMPM) | B38: 6.5 | C38: QIA sits in the MLR numerator, not the denominator — see Sheet 8.
A39: Premium taxes & fees (PMPM) | B39: 3
A40: Total non-benefit expense (PMPM) | B40: =SUM(B36:B39)
A41: Target margin (% of revenue) | B41: 0.035
A43: BENCHMARK
A44: County risk-standardized FFS per capita (PMPM) | B44: 1010 | C44: 5-year average, risk-standardized, IME removed, trended forward. From the CMS county ratebook.
A45: National FFS spending quartile | B45: 2
A46: Applicable percentage | B46: 1 | C46: 95% / 100% / 107.5% / 115% by national quartile, highest-spending to lowest.
...

Sheet 2. Base Experience
A1: Step 1 | Base Period Experience — CY2025 Incurred
A2: Paid-basis utilization and unit cost as of the March 2026 data cutoff, brought to an incurred basis by category-specific completion factors. Categories that adjudicate slowly (DME, home health) carry lower completion factors.
A4: Service Category | B4: Utilization per 1,000 | C4: Cost per Unit ($) | D4: Allowed PMPM Paid Basis ($) | E4: Completion Factor | F4: Completed Allowed PMPM ($) | G4: % of Total
A5: Inpatient Facility | B5: 240 | C5: 14500 | D5: =B5/1000*C5/12 | E5: 0.995 | F5: =D5/E5 | G5: =F5/$F$14
A6: Outpatient Facility | B6: 3000 | C6: 850 | D6: =B6/1000*C6/12 | E6: 0.985 | F6: =D6/E6 | G6: =F6/$F$14
A7: Professional | B7: 15000 | C7: 145 | D7: =B7/1000*C7/12 | E7: 0.975 | F7: =D7/E7 | G7: =F7/$F$14
A8: Skilled Nursing Facility | B8: 1100 | C8: 500 | D8: =B8/1000*C8/12 | E8: 0.99 | F8: =D8/E8 | G8: =F8/$F$14
A9: Home Health | B9: 900 | C9: 160 | D9: =B9/1000*C9/12 | E9: 0.96 | F9: =D9/E9 | G9: =F9/$F$14
A10: DME & Supplies | B10: 4500 | C10: 70 | D10: =B10/1000*C10/12 | E10: 0.945 | F10: =D10/E10 | G10: =F10/$F$14
A11: Part B Drugs | B11: 1800 | C11: 310 | D11: =B11/1000*C11/12 | E11: 0.99 | F11: =D11/E11 | G11: =F11/$F$14
A12: Emergency & Urgent Care | B12: 700 | C12: 1150 | D12: =B12/1000*C12/12 | E12: 0.992 | F12: =D12/E12 | G12: =F12/$F$14
A13: Ambulance & Transport | B13: 180 | C13: 520 | D13: =B13/1000*C13/12 | E13: 0.97 | F13: =D13/E13 | G13: =F13/$F$14
A14: TOTAL | D14: =SUM(D5:D13) | F14: =SUM(F5:F13) | G14: =SUM(G5:G13)
A16: Blended completion factor | F16: =D14/F14
A18: DECISION POINT — Completion factors are the first place a bid can be quietly optimistic. A 1-point overstatement of completion understates the base by roughly $9 PMPM here, which flows straight through trend and compounds. CMS desk review compares the factors used against the plan's own prior-year restatements.

Sheet 3. Projected Allowed
A1: Steps 2–4 | Normalize, Trend, and Adjust to the Plan Year
A2: Removes one-time items, restates the base to a 1.0-risk population, trends two years forward on separate utilization and unit-cost assumptions, then layers in known plan-year changes.
A4: Service Category | B4: Completed Allowed PMPM ($) | C4: One-Time Items ($) | D4: Adjusted Base ($) | E4: Standardized to 1.0 Risk ($) | F4: Utilization Trend | G4: Unit Cost Trend | H4: Annual Total Trend | I4: 2-Year Trend Factor | J4: Trended Standardized Allowed ($)
A5: Inpatient Facility | B5: ='2. Base Experience'!F5 | C5: ='1. Assumptions'!$B$22 | D5: =B5-C5 | E5: =D5/'1. Assumptions'!$B$21 | F5: 0.01 | G5: 0.04 | H5: =(1+F5)*(1+G5)-1 | I5: =(1+H5)^'1. Assumptions'!$B$14 | J5: =E5*I5
A6: Outpatient Facility | B6: ='2. Base Experience'!F6 | C6: 0 | D6: =B6-C6 | E6: =D6/'1. Assumptions'!$B$21 | F6: 0.025 | G6: 0.045 | H6: =(1+F6)*(1+G6)-1 | I6: =(1+H6)^'1. Assumptions'!$B$14 | J6: =E6*I6
A7: Professional | B7: ='2. Base Experience'!F7 | C7: 0 | D7: =B7-C7 | E7: =D7/'1. Assumptions'!$B$21 | F7: 0.015 | G7: 0.028 | H7: =(1+F7)*(1+G7)-1 | I7: =(1+H7)^'1. Assumptions'!$B$14 | J7: =E7*I7
A8: Skilled Nursing Facility | B8: ='2. Base Experience'!F8 | C8: 0 | D8: =B8-C8 | E8: =D8/'1. Assumptions'!$B$21 | F8: 0.005 | G8: 0.04 | H8: =(1+F8)*(1+G8)-1 | I8: =(1+H8)^'1. Assumptions'!$B$14 | J8: =E8*I8
A9: Home Health | B9: ='2. Base Experience'!F9 | C9: 0 | D9: =B9-C9 | E9: =D9/'1. Assumptions'!$B$21 | F9: 0.03 | G9: 0.03 | H9: =(1+F9)*(1+G9)-1 | I9: =(1+H9)^'1. Assumptions'!$B$14 | J9: =E9*I9
A10: DME & Supplies | B10: ='2. Base Experience'!F10 | C10: 0 | D10: =B10-C10 | E10: =D10/'1. Assumptions'!$B$21 | F10: 0.01 | G10: 0.025 | H10: =(1+F10)*(1+G10)-1 | I10: =(1+H10)^'1. Assumptions'!$B$14 | J10: =E10*I10
A11: Part B Drugs | B11: ='2. Base Experience'!F11 | C11: 0 | D11: =B11-C11 | E11: =D11/'1. Assumptions'!$B$21 | F11: 0.04 | G11: 0.065 | H11: =(1+F11)*(1+G11)-1 | I11: =(1+H11)^'1. Assumptions'!$B$14 | J11: =E11*I11
A12: Emergency & Urgent Care | B12: ='2. Base Experience'!F12 | C12: 0 | D12: =B12-C12 | E12: =D12/'1. Assumptions'!$B$21 | F12: 0.02 | G12: 0.045 | H12: =(1+F12)*(1+G12)-1 | I12: =(1+H12)^'1. Assumptions'!$B$14 | J12: =E12*I12
A13: Ambulance & Transport | B13: ='2. Base Experience'!F13 | C13: 0 | D13: =B13-C13 | E13: =D13/'1. Assumptions'!$B$21 | F13: 0.015 | G13: 0.05 | H13: =(1+F13)*(1+G13)-1 | I13: =(1+H13)^'1. Assumptions'!$B$14 | J13: =E13*I13
A14: TOTAL | B14: =SUM(B5:B13) | C14: =SUM(C5:C13) | D14: =SUM(D5:D13) | E14: =SUM(E5:E13) | J14: =SUM(J5:J13)
A16: PLAN-YEAR ADJUSTMENTS
A17: Trended standardized allowed, before adjustments | B17: =J14
A18: Hospital contract renegotiation (applied to IP + OP) | B18: =(J5+J6)*'1. Assumptions'!$B$29
A19: Post-acute utilization management program | B19: ='1. Assumptions'!$B$30
A20: Induced utilization from richer benefit design | B20: ='1. Assumptions'!$B$31
A21: New-to-Medicare mix shift (non-risk-score) | B21: ='1. Assumptions'!$B$32
A22: Net plan-year adjustments | B22: =SUM(B18:B21)
A23: PROJECTED ALLOWED PMPM — CY2027, 1.0 RISK | B23: =B17+B22
A25: Memo: implied blended annual trend | B25: =(J14/E14)^(1/'1. Assumptions'!$B$14)-1
A27: DECISION POINT — Trend is the single most scrutinized assumption in desk review and the largest source of bid risk. Splitting it into utilization and unit cost by service category is what makes it defensible: a 6.5% unit-cost trend on Part B drugs is arguable from a fee schedule, while a 6.5% blended trend on everything is not. Note also that the hospital renegotiation is a signed LOI, not an executed contract — reflecting an unsigned contract is a legitimate actuarial judgment and a predictable CMS question.

Sheet 4. Plan Liability
A1: Steps 5–7 | Plan Liability, Non-Benefit Expense, and Margin
A2: Converts projected allowed cost into the plan's revenue requirement for the basic Part A/B package.
A4: Projected allowed PMPM (CY2027, 1.0 risk) | B4: ='3. Projected Allowed'!$B$23
A5: Less: member cost sharing at Original Medicare-equivalent AV | B5: =-B4*'1. Assumptions'!$B$35 | C5: The bid is priced at Original Medicare cost-sharing levels. Richer cost sharing is funded from the rebate, not the bid — see Sheet 7.
A6: Plan-paid basic A/B benefit cost | B6: =B4+B5
A8: NON-BENEFIT EXPENSE
A9: General & administrative | B9: ='1. Assumptions'!$B$36
A10: Sales, marketing & broker commissions | B10: ='1. Assumptions'!$B$37
A11: Quality improvement activities | B11: ='1. Assumptions'!$B$38
A12: Premium taxes & fees | B12: ='1. Assumptions'!$B$39
A13: Total non-benefit expense | B13: =SUM(B9:B12)
A15: MARGIN & BID
A16: Claims + non-benefit expense | B16: =B6+B13
A17: Target margin (% of revenue) | B17: ='1. Assumptions'!$B$41
A18: Gain / loss margin (solved) | B18: =B16/(1-B17)-B16 | C18: Margin is a percentage OF REVENUE, so it is grossed up: cost / (1 - margin), not cost x (1 + margin).
A19: STANDARDIZED A/B BID (PMPM) | B19: =B16+B18
A21: Memo: margin as % of bid | B21: =B18/B19
A22: Memo: benefit expense ratio of bid | B22: =B6/B19

Sheet 5. Standardized Bid
A1: The Bid Waterfall | From Base Experience to Standardized Bid
A2: Every step from Sheet 2 through Sheet 4, in one column. This is the view a reviewer asks for first.
A4: Step | B4: Component | C4: PMPM ($) | D4: Running Total ($) | E4: Comment
A5: 1 | B5: Completed allowed cost — CY2025 base | C5: ='2. Base Experience'!F14 | D5: =C5 | E5: Sheet 2. Incurred basis, all service categories.
A6: 2 | B6: Remove one-time items | C6: =-'3. Projected Allowed'!C14 | D6: =D5+C6 | E6: Retroactive settlement stripped out of the base.
A7: 3 | B7: Standardize to 1.0 risk | C7: ='3. Projected Allowed'!E14-D6 | D7: =D6+C7 | E7: Divide by base-period RAF of 1.082. The bid must describe an average beneficiary.
A8: 4 | B8: Trend forward two years | C8: ='3. Projected Allowed'!J14-D7 | D8: =D7+C8 | E8: Category-level utilization and unit-cost trend, CY2025 to CY2027.
A9: 5 | B9: Plan-year adjustments | C9: ='3. Projected Allowed'!B22 | D9: =D8+C9 | E9: Contract renegotiation, UM program, induced demand, mix shift.
A10: 6 | B10: Less member cost sharing | C10: ='4. Plan Liability'!B5 | D10: =D9+C10 | E10: Priced at Original Medicare-equivalent actuarial value.
A11: 7 | B11: Add non-benefit expense | C11: ='4. Plan Liability'!B13 | D11: =D10+C11 | E11: Admin, distribution, QIA, taxes and fees.
A12: 8 | B12: Add gain / loss margin | C12: ='4. Plan Liability'!B18 | D12: =D11+C12 | E12: Grossed up to a 3.5% margin on revenue.
B13: STANDARDIZED A/B BID | D13: =D12
B15: Tie-out check vs Sheet 4 (must be zero) | D15: =D13-'4. Plan Liability'!B19

Sheet 6. Benchmark & Rebate
A1: Step 8 | Benchmark Comparison, Savings, Rebate, and Payment
A2: Where the plan's bid meets the CMS county ratebook, and where Star Ratings turn into dollars.
A4: BENCHMARK BUILD
A5: County risk-standardized FFS per capita | B5: ='1. Assumptions'!$B$44
A6: National FFS spending quartile | B6: ='1. Assumptions'!$B$45
A7: Applicable percentage | B7: ='1. Assumptions'!$B$46
A8: Base benchmark | B8: =B5*B7
A9: Quality bonus (4.0+ Stars) | B9: =B8*'1. Assumptions'!$B$47
A10: FINAL BENCHMARK | B10: =B8+B9 | C10: A statutory cap can bind here in a small number of counties, holding the benchmark to its grown pre-ACA level. Not binding in this example.
A12: BID vs BENCHMARK
A13: Standardized A/B bid | B13: ='5. Standardized Bid'!D13
A14: Savings (benchmark less bid) | B14: =B10-B13
A15: Rebate share (Star-based) | B15: ='1. Assumptions'!$B$48
A16: Rebate to plan (earmarked for member value) | B16: =B14*B15
A17: Government share — never paid out, stays in the Trust Funds | B17: =B14-B16
A18: Member basic premium | B18: =MAX(0,B13-B10) | C18: Zero whenever the bid lands under the benchmark. A bid above the benchmark becomes a member premium.
A20: PAYMENT
A21: Bid + rebate (standardized, 1.0 risk) | B21: =B13+B16
A22: Payment RAF | B22: ='1. Assumptions'!$B$26
A23: PAYMENT PMPM (risk-adjusted) | B23: =B21*B22
A24: Members | B24: ='1. Assumptions'!$B$15
A25: Annual plan revenue | B25: =B23*12*B24
A27: DECISION POINT — The plan does not choose its benchmark, but it does choose which counties to bid in. A county one quartile lower pays 7.5 points more of its own FFS cost. Service-area strategy is set months before any of this arithmetic runs.

Sheet 7. Rebate Allocation
A1: Step 9 | Rebate Allocation — Turning Savings into Member Value
A2: The rebate cannot flow to the bottom line as ordinary profit. It must be spent here. Margin on delivering these benefits is the balancing item.
A4: Rebate available (PMPM) | B4: ='6. Benchmark & Rebate'!B16
A6: REDUCED COST SHARING
A7: Buy-down of A/B cost sharing below Original Medicare | B7: 46
A9: SUPPLEMENTAL BENEFITS
A10: Comprehensive dental | B10: 18.5
A11: Vision | B11: 3.2
A12: Hearing | B12: 4.8
A13: OTC / flex card | B13: 8.4
A14: Fitness | B14: 3.1
A15: Subtotal — supplemental benefits | B15: =SUM(B10:B14)
A17: Total direct member value | B17: =B7+B15
A18: Administrative load on rebate-funded benefits | B18: 11
A19: Margin on rebate-funded benefits (balancing item) | B19: =B4-B17-B18
A20: Total allocated | B20: =B17+B18+B19
A21: Check — unallocated rebate (must be zero) | B21: =B4-B20
A23: Memo: direct member value as % of rebate | B23: =B17/B4
A24: Memo: member cost sharing after buy-down (PMPM) | B24: =-'4. Plan Liability'!B5-B7
A26: DECISION POINT — This is the most commercially consequential page in the bid. The same $99.71 can be spent on a headline $0 deductible, a large OTC card that markets well, or a Part B giveback that shows up as a number on Plan Finder. Each buys a different amount of enrollment, and the plan is guessing at competitors who are making the same call behind the same June deadline.

Sheet 8. Compliance Tests
A1: Step 10 | Compliance Tests
A2: Run before certification. A bid that fails any of these does not get filed.
A4: MEDICAL LOSS RATIO
A5: Revenue PMPM (risk-adjusted) | B5: ='6. Benchmark & Rebate'!B23
A6: Basic A/B claims, risk-adjusted | B6: ='4. Plan Liability'!B6*'1. Assumptions'!$B$26
A7: Rebate-funded benefits, risk-adjusted | B7: ='7. Rebate Allocation'!B17*'1. Assumptions'!$B$26
A8: Quality improvement activities, risk-adjusted | B8: ='1. Assumptions'!$B$38*'1. Assumptions'!$B$26
A9: MLR numerator | B9: =SUM(B6:B8)
A10: Projected MLR | B10: =B9/B5
A11: CMS minimum | B11: ='1. Assumptions'!$B$52
A12: Cushion | B12: =B10-B11
A13: Result | B13: =IF(B10>=B11,"PASS","FAIL") | C13: Below 85% triggers remittance; sustained failure means an enrollment freeze and ultimately contract termination.
A15: TOTAL BENEFICIARY COST
A16: CY2026 TBC (premium + cost sharing) | B16: ='1. Assumptions'!$B$51
A17: CY2027 member premium | B17: ='6. Benchmark & Rebate'!B18
A18: CY2027 member cost sharing (after rebate buy-down) | B18: ='7. Rebate Allocation'!B24
A19: CY2027 TBC | B19: =B17+B18
A20: Year-over-year change | B20: =B19-B16
A21: Result | B21: =IF(B20<=0,"PASS - beneficiary cost decreases","REVIEW vs CMS threshold")
A23: MAXIMUM OUT-OF-POCKET
A24: Plan in-network MOOP | B24: ='1. Assumptions'!$B$53
A25: CMS mandatory limit | B25: ='1. Assumptions'!$B$54
A26: Result | B26: =IF(B24<=B25,"PASS","FAIL")
A28: MARGIN
A29: Bid margin | B29: ='4. Plan Liability'!B18
A30: Rebate-funded margin | B30: ='7. Rebate Allocation'!B19
A31: Total margin (standardized PMPM) | B31: =B29+B30
A32: Total margin as % of standardized revenue | B32: =B31/'6. Benchmark & Rebate'!B21

Sheet 9. Sensitivity
A1: Scenario Sensitivity
A2: Each row re-solves the bid with one lever changed. Trend scenarios scale projected allowed cost off the implied blended trend on Sheet 3 — an approximation, close enough for direction and magnitude but not a substitute for re-running the category grid. Every scenario holds target margin constant and lets the rebate absorb the difference; a plan could instead hold benefits and let margin absorb it.
A4: Scenario | B4: Star Rating | C4: QBP | D4: Rebate Share | E4: Trend Delta (pp/yr) | F4: RAF Factor | G4: Applicable % | H4: Benchmark ($) | I4: Projected Allowed ($) | J4: Plan-Paid Basic ($) | K4: Standardized Bid ($) | L4: Savings ($) | M4: Rebate ($) | N4: Payment RAF | O4: Revenue PMPM ($) | P4: Annual Revenue ($) | Q4: Annual Rev vs Base ($) | R4: Rebate vs Base ($ PMPM) | S4: Annual Rebate vs Base ($)
A5: Base case | B5: 4 | C5: 0.05 | D5: 0.65 | E5: 0 | F5: 1 | G5: 1 | H5: ='1. Assumptions'!$B$44*G5*(1+C5) | I5: ='3. Projected Allowed'!$B$23*((1+'3. Projected Allowed'!$B$25+E5)/(1+'3. Projected Allowed'!$B$25))^'1. Assumptions'!$B$14 | J5: =I5*(1-'1. Assumptions'!$B$35) | K5: =(J5+'1. Assumptions'!$B$40)/(1-'1. Assumptions'!$B$41) | L5: =H5-K5 | M5: =L5*D5 | N5: ='1. Assumptions'!$B$26*F5 | O5: =(K5+M5)*N5 | P5: =O5*12*'1. Assumptions'!$B$15 | Q5: =P5-$P$5 | R5: =M5-$M$5 | S5: =R5*12*'1. Assumptions'!$B$15
A6: Stars fall to 3.5 — QBP lost | B6: 3.5 | C6: 0 | D6: 0.65 | E6: 0 | F6: 1 | G6: 1 | H6: ='1. Assumptions'!$B$44*G6*(1+C6) | I6: ='3. Projected Allowed'!$B$23*((1+'3. Projected Allowed'!$B$25+E6)/(1+'3. Projected Allowed'!$B$25))^'1. Assumptions'!$B$14 | J6: =I6*(1-'1. Assumptions'!$B$35) | K6: =(J6+'1. Assumptions'!$B$40)/(1-'1. Assumptions'!$B$41) | L6: =H6-K6 | M6: =L6*D6 | N6: ='1. Assumptions'!$B$26*F6 | O6: =(K6+M6)*N6 | P6: =O6*12*'1. Assumptions'!$B$15 | Q6: =P6-$P$5 | R6: =M6-$M$5 | S6: =R6*12*'1. Assumptions'!$B$15
A7: Stars rise to 4.5 — 70% share | B7: 4.5 | C7: 0.05 | D7: 0.7 | E7: 0 | F7: 1 | G7: 1 | H7: ='1. Assumptions'!$B$44*G7*(1+C7) | I7: ='3. Projected Allowed'!$B$23*((1+'3. Projected Allowed'!$B$25+E7)/(1+'3. Projected Allowed'!$B$25))^'1. Assumptions'!$B$14 | J7: =I7*(1-'1. Assumptions'!$B$35) | K7: =(J7+'1. Assumptions'!$B$40)/(1-'1. Assumptions'!$B$41) | L7: =H7-K7 | M7: =L7*D7 | N7: ='1. Assumptions'!$B$26*F7 | O7: =(K7+M7)*N7 | P7: =O7*12*'1. Assumptions'!$B$15 | Q7: =P7-$P$5 | R7: =M7-$M$5 | S7: =R7*12*'1. Assumptions'!$B$15
A8: Trend 1 pt/yr higher | B8: 4 | C8: 0.05 | D8: 0.65 | E8: 0.01 | F8: 1 | G8: 1 | H8: ='1. Assumptions'!$B$44*G8*(1+C8) | I8: ='3. Projected Allowed'!$B$23*((1+'3. Projected Allowed'!$B$25+E8)/(1+'3. Projected Allowed'!$B$25))^'1. Assumptions'!$B$14 | J8: =I8*(1-'1. Assumptions'!$B$35) | K8: =(J8+'1. Assumptions'!$B$40)/(1-'1. Assumptions'!$B$41) | L8: =H8-K8 | M8: =L8*D8 | N8: ='1. Assumptions'!$B$26*F8 | O8: =(K8+M8)*N8 | P8: =O8*12*'1. Assumptions'!$B$15 | Q8: =P8-$P$5 | R8: =M8-$M$5 | S8: =R8*12*'1. Assumptions'!$B$15
A9: Trend 1 pt/yr lower | B9: 4 | C9: 0.05 | D9: 0.65 | E9: -0.01 | F9: 1 | G9: 1 | H9: ='1. Assumptions'!$B$44*G9*(1+C9) | I9: ='3. Projected Allowed'!$B$23*((1+'3. Projected Allowed'!$B$25+E9)/(1+'3. Projected Allowed'!$B$25))^'1. Assumptions'!$B$14 | J9: =I9*(1-'1. Assumptions'!$B$35) | K9: =(J9+'1. Assumptions'!$B$40)/(1-'1. Assumptions'!$B$41) | L9: =H9-K9 | M9: =L9*D9 | N9: ='1. Assumptions'!$B$26*F9 | O9: =(K9+M9)*N9 | P9: =O9*12*'1. Assumptions'!$B$15 | Q9: =P9-$P$5 | R9: =M9-$M$5 | S9: =R9*12*'1. Assumptions'!$B$15
A10: RAF 3% below projection | B10: 4 | C10: 0.05 | D10: 0.65 | E10: 0 | F10: 0.97 | G10: 1 | H10: ='1. Assumptions'!$B$44*G10*(1+C10) | I10: ='3. Projected Allowed'!$B$23*((1+'3. Projected Allowed'!$B$25+E10)/(1+'3. Projected Allowed'!$B$25))^'1. Assumptions'!$B$14 | J10: =I10*(1-'1. Assumptions'!$B$35) | K10: =(J10+'1. Assumptions'!$B$40)/(1-'1. Assumptions'!$B$41) | L10: =H10-K10 | M10: =L10*D10 | N10: ='1. Assumptions'!$B$26*F10 | O10: =(K10+M10)*N10 | P10: =O10*12*'1. Assumptions'!$B$15 | Q10: =P10-$P$5 | R10: =M10-$M$5 | S10: =R10*12*'1. Assumptions'!$B$15
A11: County drops to quartile 1 (95%) | B11: 4 | C11: 0.05 | D11: 0.65 | E11: 0 | F11: 1 | G11: 0.95 | H11: ='1. Assumptions'!$B$44*G11*(1+C11) | I11: ='3. Projected Allowed'!$B$23*((1+'3. Projected Allowed'!$B$25+E11)/(1+'3. Projected Allowed'!$B$25))^'1. Assumptions'!$B$14 | J11: =I11*(1-'1. Assumptions'!$B$35) | K11: =(J11+'1. Assumptions'!$B$40)/(1-'1. Assumptions'!$B$41) | L11: =H11-K11 | M11: =L11*D11 | N11: ='1. Assumptions'!$B$26*F11 | O11: =(K11+M11)*N11 | P11: =O11*12*'1. Assumptions'!$B$15 | Q11: =P11-$P$5 | R11: =M11-$M$5 | S11: =R11*12*'1. Assumptions'!$B$15
A13: READING THIS TABLE — The Star scenarios are the headline: losing the 4.0 threshold costs the plan nothing in margin but strips roughly $33 PMPM out of the member benefit package, which is what actually loses enrollment. The trend scenarios show the asymmetry actuaries live with: guess trend too low and the margin is gone with no way to reprice for twelve months; guess too high and the benefit package is uncompetitive against plans that guessed better.
